Workbook

Sheet 1.Distancias
A1: Distancias calculadas sobre plano para las tomas. Sobre ellas se calculan todos los valores posteriores de atenuación.
B4: Distancias (m) | E4: RS -> RS
A5: Tomas | B5: PAU -> TOMA | C5: Reg.Secundario -> PAU | E5: (vertical) m.
A6: Ático-Dorm.3 | B6: 7.97 | C6: 2.05 | E6: 3
A7: Ático-Dorm.2 | B7: 10.29
A8: Ático-Dorm.Ppal. | B8: 10.95
A9: Ático-Cocina | B9: 8.1
A10: Ático-Salón* | B10: 4.37
A11: 8B-Dorm.3 | B11: 2.67 | C11: 6.25
A12: 8B-Dorm.2 | B12: 6.37
A13: 8B-Dorm.Ppal. | B13: 5.45
A14: 8B-Cocina | B14: 0.85
A15: 8B-Salón | B15: 1.7
A16: 8A-Dorm.3 | B16: 2.67 | C16: 3.49
A17: 8A-Dorm.2 | B17: 6.37
A18: 8A-Dorm.Ppal. | B18: 5.45
A19: 8A-Cocina | B19: 0.85
A20: 8A-Salón | B20: 1.7
A21: 7B-Dorm.3 | B21: 2.67 | C21: 6.25
A22: 7B-Dorm.2 | B22: 6.37
A23: 7B-Dorm.Ppal. | B23: 5.45
A24: 7B-Cocina | B24: 0.85
A25: 7B-Salón | B25: 1.7
A26: 7A-Dorm.3 | B26: 2.67 | C26: 3.49
A27: 7A-Dorm.2 | B27: 6.37
A28: 7A-Dorm.Ppal. | B28: 5.45
A29: 7A-Cocina | B29: 0.85
A30: 7A-Salón | B30: 1.7
A31: 6B-Dorm.3 | B31: 2.67 | C31: 6.25
A32: 6B-Dorm.2 | B32: 6.37
A33: 6B-Dorm.Ppal. | B33: 5.45
A34: 6B-Cocina | B34: 0.85
A35: 6B-Salón | B35: 1.7
A36: 6A-Dorm.3 | B36: 2.67 | C36: 3.49
A37: 6A-Dorm.2 | B37: 6.37
A38: 6A-Dorm.Ppal. | B38: 5.45
A39: 6A-Cocina | B39: 0.85
A40: 6A-Salón | B40: 1.7
A41: 5B-Dorm.3 | B41: 2.67 | C41: 6.25
A42: 5B-Dorm.2 | B42: 6.37
...

Sheet 2.Red
A1: Se eligen aquí los elementos para el diseño de la red de distribución / dispersión / interior de usuario.
A6: CABLE | D6: REPARTIDOR | H6: PAU REPARTIDOR
A7: Frecuencia (MHz) | B7: Atenuación dB/m | D7: Tipo | E7: Nº salidas | F7: At.Inserción V/U | H7: Tipo | I7: Nº salidas | J7: At.Inserción V/U | K7: At.Inserción FI
A8: 15 | B8: 0.03 | D8: 1 | E8: 2 | F8: 4 | H8: 1 | I8: 5 | J8: 11 | K8: 10
A9: 100 | B9: 0.06
A10: 200 | B10: 0.08 | D10: Solo se usa en banda terrena (cabecera)
A11: 470 | B11: 0.14
A12: 694 | B12: 0.15
A13: 862 | B13: 0.17
A14: 950 | B14: 0.19
A15: 1350 | B15: 0.23 | D15: MEZCLADOR | G15: TOMA
A16: 1750 | B16: 0.25 | D16: At. Inserción V/U | E16: At. Inserción FI | G16: At. FM (87,5..108 MHZ) | H16: At. VHF (125..470) MHz | I16: At. UHF (470..862) MHz | J16: At. FI (950..2150) MHz
A17: 2150 | B17: 0.29 | D17: 1.5 | E17: 1.8 | G17: 0.6 | H17: 0.6 | I17: 0.6 | J17: 1.5
A18: 2300 | B18: 0.3
A20: DERIVADORES
A21: Localización | B21: Tipo | C21: Nº salidas | D21: At. Derivación V/U | E21: At. Inserción V/U | F21: At. Derivación FI | G21: At. Inserción FI
A22: Ático | B22: D | C22: 2 | D22: 24 | E22: 1.5 | F22: 23 | G22: 2
A23: Planta 8 | B23: D | C23: 2 | D23: 24 | E23: 1.5 | F23: 23 | G23: 2
A24: Planta 7 | B24: D | C24: 2 | D24: 24 | E24: 1.5 | F24: 23 | G24: 2
A25: Planta 6 | B25: C | C25: 2 | D25: 20 | E25: 1.5 | F25: 19 | G25: 2
A26: Planta 5 | B26: C | C26: 2 | D26: 20 | E26: 1.5 | F26: 19 | G26: 2
A27: Planta 4 | B27: C | C27: 2 | D27: 20 | E27: 1.5 | F27: 19 | G27: 2
A28: Planta 3 | B28: B | C28: 2 | D28: 16 | E28: 2 | F28: 15 | G28: 2.5
A29: Planta 2 | B29: B | C29: 2 | D29: 16 | E29: 2 | F29: 15 | G29: 2.5
A30: Planta 1 | B30: A | C30: 2 | D30: 12 | E30: 2.3 | F30: 11 | G30: 3.4

Sheet 3.CalculoRedRTV-SAT
A1: Se exponen aquí los resultados de la instalación RTV-SAT.
H5: Nivel señal salida amplificadores 47-694 MHz (dBuV) | K5: =MEDIAN(MAX(P20:S20),MIN(P20:S20)) -> 99.7325 | Q5: FM | R5: DAB | S5: TDT | T5: FI
H6: Nivel señal salida amplificadores 950-2150 MHz (dBuV) | K6: =MEDIAN(T20:U20) -> 107.0748 | P6: Toma mejor | Q6: Ático Salón | R6: Ático Salón | S6: Ático Salón | T6: Ático Salón
P7: Toma peor | Q7: 4B Dormitorio2 | R7: 4B Dormitorio2 | S7: 2B Dormitorio2 | T7: 2B Dormitorio2
B8: Atenuación (dB) [Salida Cabecera (amplif. monocanal)] --> [Salida Toma] At(dB)ÁticoDorm3 =At(dB)Ático+At(dB)ÁticoA+DistanciaPAUToma* At.cable[f] (dB/m)+At.Toma … At(dB)1ºPlantaASalón =At(dB)1ºPlanta+At(dB)1ºPlantaA+DistanciaPAUToma* At.cable[f] (dB/m)+At.Toma | H8: Nivel de señal en Toma (dBuV) S(dB)ÁticoDorm3 = Ssamp - At(dB)ÁticoDorm3
B9: FM | C9: DAB | D9: TDT | F9: FI | H9: FM | I9: DAB | J9: TDT | L9: FI | O9: Atenuación(dB) | P9: FM | Q9: DAB | R9: TDT | T9: FI | V9: Atenuación(dB)
A10: Toma | B10: ( f = 100 MHz ) | C10: ( f = 200 MHz ) | D10: ( f = 470 MHz ) | E10: ( f = 862 MHz ) | F10: ( f = 950 MHz ) | G10: ( f = 2150 MHz ) | H10: ( f = 100 MHz ) | I10: ( f = 200 MHz ) | J10: ( f = 470 MHz ) | K10: ( f = 862 MHz ) | L10: ( f = 950 MHz ) | M10: ( f = 2150 MHz ) | P10: ( f = 100 MHz ) | Q10: ( f = 200 MHz ) | R10: ( f = 470 MHz ) | S10: ( f = 862 MHz ) | T10: ( f = 950 MHz ) | U10: ( f = 2150 MHz )
A11: Ático-Dorm.3 | B11: =B$113+B$126+'1.Distancias'!$B6*'2.Red'!$B$9+'2.Red'!$G$17 -> 41.8812 | C11: =C$113+C$126+'1.Distancias'!$B6*'2.Red'!$B$10+'2.Red'!$H$17 -> 42.1416 | D11: =D$113+D$126+'1.Distancias'!$B6*'2.Red'!$B$11+'2.Red'!$I$17 -> 42.9228 | E11: =E$113+E$126+'1.Distancias'!$B6*'2.Red'!$B$13+'2.Red'!$I$17 -> 43.3134 | F11: =F$113+F$126+'1.Distancias'!$B6*'2.Red'!$B$14+'2.Red'!$J$17 -> 38.7738 | G11: =G$113+G$126+'1.Distancias'!$B6*'2.Red'!$B$17+'2.Red'!$J$17 -> 40.0758 | H11: =$K$5-B11 -> 57.8513 | I11: =$K$5-C11 -> 57.5909 | J11: =$K$5-D11 -> 56.8097 | K11: =$K$5-E11 -> 56.4191 | L11: =$K$6-F11 -> 68.301 | M11: =$K$6-G11 -> 66.999 | O11: Toma mejor | P11: =B98 -> 41.6652 | Q11: =C98 -> 41.8536 | R11: =D98 -> 42.4188 | S11: =E98 -> 42.7014 | T11: =F98 -> 38.0898 | U11: =G98 -> 39.0318 | V11: Toma mejor
A12: Ático-Dorm.2 | B12: =B$113+B$126+'1.Distancias'!$B7*'2.Red'!$B$9+'2.Red'!$G$17 -> 42.0204 | C12: =C$113+C$126+'1.Distancias'!$B7*'2.Red'!$B$10+'2.Red'!$H$17 -> 42.3272 | D12: =D$113+D$126+'1.Distancias'!$B7*'2.Red'!$B$11+'2.Red'!$I$17 -> 43.2476 | E12: =E$113+E$126+'1.Distancias'!$B7*'2.Red'!$B$13+'2.Red'!$I$17 -> 43.7078 | F12: =F$113+F$126+'1.Distancias'!$B7*'2.Red'!$B$14+'2.Red'!$J$17 -> 39.2146 | G12: =G$113+G$126+'1.Distancias'!$B7*'2.Red'!$B$17+'2.Red'!$J$17 -> 40.7486 | H12: =$K$5-B12 -> 57.7121 | I12: =$K$5-C12 -> 57.4053 | J12: =$K$5-D12 -> 56.4849 | K12: =$K$5-E12 -> 56.0247 | L12: =$K$6-F12 -> 67.8602 | M12: =$K$6-G12 -> 66.3262 | O12: Toma peor | P12: =B97 -> 46.4372 | Q12: =C97 -> 47.0496 | R12: =D97 -> 49.2268 | S12: =E97 -> 50.3254 | T12: =F97 -> 49.7578 | U12: =G97 -> 53.4198 | V12: Toma peor
A13: Ático-Dorm.Ppal. | B13: =B$113+B$126+'1.Distancias'!$B8*'2.Red'!$B$9+'2.Red'!$G$17 -> 42.06 | C13: =C$113+C$126+'1.Distancias'!$B8*'2.Red'!$B$10+'2.Red'!$H$17 -> 42.38 | D13: =D$113+D$126+'1.Distancias'!$B8*'2.Red'!$B$11+'2.Red'!$I$17 -> 43.34 | E13: =E$113+E$126+'1.Distancias'!$B8*'2.Red'!$B$13+'2.Red'!$I$17 -> 43.82 | F13: =F$113+F$126+'1.Distancias'!$B8*'2.Red'!$B$14+'2.Red'!$J$17 -> 39.34 | G13: =G$113+G$126+'1.Distancias'!$B8*'2.Red'!$B$17+'2.Red'!$J$17 -> 40.94 | H13: =$K$5-B13 -> 57.6725 | I13: =$K$5-C13 -> 57.3525 | J13: =$K$5-D13 -> 56.3925 | K13: =$K$5-E13 -> 55.9125 | L13: =$K$6-F13 -> 67.7348 | M13: =$K$6-G13 -> 66.1348
A14: Ático-Cocina | B14: =B$113+B$126+'1.Distancias'!$B9*'2.Red'!$B$9+'2.Red'!$G$17 -> 41.889 | C14: =C$113+C$126+'1.Distancias'!$B9*'2.Red'!$B$10+'2.Red'!$H$17 -> 42.152 | D14: =D$113+D$126+'1.Distancias'!$B9*'2.Red'!$B$11+'2.Red'!$I$17 -> 42.941 | E14: =E$113+E$126+'1.Distancias'!$B9*'2.Red'!$B$13+'2.Red'!$I$17 -> 43.3355 | F14: =F$113+F$126+'1.Distancias'!$B9*'2.Red'!$B$14+'2.Red'!$J$17 -> 38.7985 | G14: =G$113+G$126+'1.Distancias'!$B9*'2.Red'!$B$17+'2.Red'!$J$17 -> 40.1135 | H14: =$K$5-B14 -> 57.8435 | I14: =$K$5-C14 -> 57.5805 | J14: =$K$5-D14 -> 56.7915 | K14: =$K$5-E14 -> 56.397 | L14: =$K$6-F14 -> 68.2763 | M14: =$K$6-G14 -> 66.9613 | O14: Nivel de señal salida amplificadores necesaria(dBuV) | P14: FM | Q14: DAB | R14: TDT | T14: FI | V14: Nivel de señal salida amplificadores necesaria(dBuV)
A15: Ático-Salón | B15: =B$113+B$126+'1.Distancias'!$B10*'2.Red'!$B$9+'2.Red'!$G$17 -> 41.6652 | C15: =C$113+C$126+'1.Distancias'!$B10*'2.Red'!$B$10+'2.Red'!$H$17 -> 41.8536 | D15: =D$113+D$126+'1.Distancias'!$B10*'2.Red'!$B$11+'2.Red'!$I$17 -> 42.4188 | E15: =E$113+E$126+'1.Distancias'!$B10*'2.Red'!$B$13+'2.Red'!$I$17 -> 42.7014 | F15: =F$113+F$126+'1.Distancias'!$B10*'2.Red'!$B$14+'2.Red'!$J$17 -> 38.0898 | G15: =G$113+G$126+'1.Distancias'!$B10*'2.Red'!$B$17+'2.Red'!$J$17 -> 39.0318 | H15: =$K$5-B15 -> 58.0673 | I15: =$K$5-C15 -> 57.8789 | J15: =$K$5-D15 -> 57.3137 | K15: =$K$5-E15 -> 57.0311 | L15: =$K$6-F15 -> 68.985 | M15: =$K$6-G15 -> 68.043 | P15: ( f = 100 MHz ) | Q15: ( f = 200 MHz ) | R15: ( f = 470 MHz ) | S15: ( f = 862 MHz ) | T15: ( f = 950 MHz ) | U15: ( f = 2150 MHz )
A16: 8B-Dorm.3 | B16: =B$114+B$127+'1.Distancias'!$B11*'2.Red'!$B$9+'2.Red'!$G$17 -> 43.4952 | C16: =C$114+C$127+'1.Distancias'!$B11*'2.Red'!$B$10+'2.Red'!$H$17 -> 43.7936 | D16: =D$114+D$127+'1.Distancias'!$B11*'2.Red'!$B$11+'2.Red'!$I$17 -> 44.6888 | E16: =E$114+E$127+'1.Distancias'!$B11*'2.Red'!$B$13+'2.Red'!$I$17 -> 45.1364 | F16: =F$114+F$127+'1.Distancias'!$B11*'2.Red'!$B$14+'2.Red'!$J$17 -> 41.1348 | G16: =G$114+G$127+'1.Distancias'!$B11*'2.Red'!$B$17+'2.Red'!$J$17 -> 42.6268 | H16: =$K$5-B16 -> 56.2373 | I16: =$K$5-C16 -> 55.9389 | J16: =$K$5-D16 -> 55.0437 | K16: =$K$5-E16 -> 54.5961 | L16: =$K$6-F16 -> 65.94 | M16: =$K$6-G16 -> 64.448 | O16: Valor máximo requerido | P16: 70 | Q16: 70 | R16: 70 | S16: 70 | T16: 77 | U16: 77 | V16: Valor máximo requerido
A17: 8B-Dorm.2 | B17: =B$114+B$127+'1.Distancias'!$B12*'2.Red'!$B$9+'2.Red'!$G$17 -> 43.7172 | C17: =C$114+C$127+'1.Distancias'!$B12*'2.Red'!$B$10+'2.Red'!$H$17 -> 44.0896 | D17: =D$114+D$127+'1.Distancias'!$B12*'2.Red'!$B$11+'2.Red'!$I$17 -> 45.2068 | E17: =E$114+E$127+'1.Distancias'!$B12*'2.Red'!$B$13+'2.Red'!$I$17 -> 45.7654 | F17: =F$114+F$127+'1.Distancias'!$B12*'2.Red'!$B$14+'2.Red'!$J$17 -> 41.8378 | G17: =G$114+G$127+'1.Distancias'!$B12*'2.Red'!$B$17+'2.Red'!$J$17 -> 43.6998 | H17: =$K$5-B17 -> 56.0153 | I17: =$K$5-C17 -> 55.6429 | J17: =$K$5-D17 -> 54.5257 | K17: =$K$5-E17 -> 53.9671 | L17: =$K$6-F17 -> 65.237 | M17: =$K$6-G17 -> 63.375 | O17: Valor mínmo requerido | P17: 40 | Q17: 30 | R17: 47 | S17: 47 | T17: 47 | U17: 47 | V17: Valor mínmo requerido
A18: 8B-Dorm.Ppal. | B18: =B$114+B$127+'1.Distancias'!$B13*'2.Red'!$B$9+'2.Red'!$G$17 -> 43.662 | C18: =C$114+C$127+'1.Distancias'!$B13*'2.Red'!$B$10+'2.Red'!$H$17 -> 44.016 | D18: =D$114+D$127+'1.Distancias'!$B13*'2.Red'!$B$11+'2.Red'!$I$17 -> 45.078 | E18: =E$114+E$127+'1.Distancias'!$B13*'2.Red'!$B$13+'2.Red'!$I$17 -> 45.609 | F18: =F$114+F$127+'1.Distancias'!$B13*'2.Red'!$B$14+'2.Red'!$J$17 -> 41.663 | G18: =G$114+G$127+'1.Distancias'!$B13*'2.Red'!$B$17+'2.Red'!$J$17 -> 43.433 | H18: =$K$5-B18 -> 56.0705 | I18: =$K$5-C18 -> 55.7165 | J18: =$K$5-D18 -> 54.6545 | K18: =$K$5-E18 -> 54.1235 | L18: =$K$6-F18 -> 65.4118 | M18: =$K$6-G18 -> 63.6418 | O18: Smax=AtomaMejor + Valor máx req | P18: =P11+P16 -> 111.6652 | Q18: =Q11+Q16 -> 111.8536 | R18: =R11+R16 -> 112.4188 | S18: =S11+S16 -> 112.7014 | T18: =T11+T16 -> 115.0898 | U18: =U11+U16 -> 116.0318 | V18: Smax=AtomaMejor + Valor máx req
A19: 8B-Cocina | B19: =B$114+B$127+'1.Distancias'!$B14*'2.Red'!$B$9+'2.Red'!$G$17 -> 43.386 | C19: =C$114+C$127+'1.Distancias'!$B14*'2.Red'!$B$10+'2.Red'!$H$17 -> 43.648 | D19: =D$114+D$127+'1.Distancias'!$B14*'2.Red'!$B$11+'2.Red'!$I$17 -> 44.434 | E19: =E$114+E$127+'1.Distancias'!$B14*'2.Red'!$B$13+'2.Red'!$I$17 -> 44.827 | F19: =F$114+F$127+'1.Distancias'!$B14*'2.Red'!$B$14+'2.Red'!$J$17 -> 40.789 | G19: =G$114+G$127+'1.Distancias'!$B14*'2.Red'!$B$17+'2.Red'!$J$17 -> 42.099 | H19: =$K$5-B19 -> 56.3465 | I19: =$K$5-C19 -> 56.0845 | J19: =$K$5-D19 -> 55.2985 | K19: =$K$5-E19 -> 54.9055 | L19: =$K$6-F19 -> 66.2858 | M19: =$K$6-G19 -> 64.9758 | O19: Smin=AtomaPeor + Valor mín req | P19: =P12+P17 -> 86.4372 | Q19: =Q12+Q17 -> 77.0496 | R19: =R12+R17 -> 96.2268 | S19: =S12+S17 -> 97.3254 | T19: =T12+T17 -> 96.7578 | U19: =U12+U17 -> 100.4198 | V19: Smin=AtomaPeor + Valor mín req
A20: 8B-Salón | B20: =B$114+B$127+'1.Distancias'!$B15*'2.Red'!$B$9+'2.Red'!$G$17 -> 43.437 | C20: =C$114+C$127+'1.Distancias'!$B15*'2.Red'!$B$10+'2.Red'!$H$17 -> 43.716 | D20: =D$114+D$127+'1.Distancias'!$B15*'2.Red'!$B$11+'2.Red'!$I$17 -> 44.553 | E20: =E$114+E$127+'1.Distancias'!$B15*'2.Red'!$B$13+'2.Red'!$I$17 -> 44.9715 | F20: =F$114+F$127+'1.Distancias'!$B15*'2.Red'!$B$14+'2.Red'!$J$17 -> 40.9505 | G20: =G$114+G$127+'1.Distancias'!$B15*'2.Red'!$B$17+'2.Red'!$J$17 -> 42.3455 | H20: =$K$5-B20 -> 56.2955 | I20: =$K$5-C20 -> 56.0165 | J20: =$K$5-D20 -> 55.1795 | K20: =$K$5-E20 -> 54.761 | L20: =$K$6-F20 -> 66.1243 | M20: =$K$6-G20 -> 64.7293 | O20: Media(Smax, Smin) | P20: =MEDIAN(P18:P19) -> 99.0512 | Q20: =MEDIAN(Q18:Q19) -> 94.4516 | R20: =MEDIAN(R18:R19) -> 104.3228 | S20: =MEDIAN(S18:S19) -> 105.0134 | T20: =MEDIAN(T18:T19) -> 105.9238 | U20: =MEDIAN(U18:U19) -> 108.2258 | V20: Media(Smax, Smin)
A21: 8A-Dorm.3 | B21: =B$114+B$128+'1.Distancias'!$B16*'2.Red'!$B$9+'2.Red'!$G$17 -> 43.3296 | C21: =C$114+C$128+'1.Distancias'!$B16*'2.Red'!$B$10+'2.Red'!$H$17 -> 43.5728 | D21: =D$114+D$128+'1.Distancias'!$B16*'2.Red'!$B$11+'2.Red'!$I$17 -> 44.3024 | E21: =E$114+E$128+'1.Distancias'!$B16*'2.Red'!$B$13+'2.Red'!$I$17 -> 44.6672 | F21: =F$114+F$128+'1.Distancias'!$B16*'2.Red'!$B$14+'2.Red'!$J$17 -> 40.6104 | G21: =G$114+G$128+'1.Distancias'!$B16*'2.Red'!$B$17+'2.Red'!$J$17 -> 41.8264 | H21: =$K$5-B21 -> 56.4029 | I21: =$K$5-C21 -> 56.1597 | J21: =$K$5-D21 -> 55.4301 | K21: =$K$5-E21 -> 55.0653 | L21: =$K$6-F21 -> 66.4644 | M21: =$K$6-G21 -> 65.2484
A22: 8A-Dorm.2 | B22: =B$114+B$128+'1.Distancias'!$B17*'2.Red'!$B$9+'2.Red'!$G$17 -> 43.5516 | C22: =C$114+C$128+'1.Distancias'!$B17*'2.Red'!$B$10+'2.Red'!$H$17 -> 43.8688 | D22: =D$114+D$128+'1.Distancias'!$B17*'2.Red'!$B$11+'2.Red'!$I$17 -> 44.8204 | E22: =E$114+E$128+'1.Distancias'!$B17*'2.Red'!$B$13+'2.Red'!$I$17 -> 45.2962 | F22: =F$114+F$128+'1.Distancias'!$B17*'2.Red'!$B$14+'2.Red'!$J$17 -> 41.3134 | G22: =G$114+G$128+'1.Distancias'!$B17*'2.Red'!$B$17+'2.Red'!$J$17 -> 42.8994 | H22: =$K$5-B22 -> 56.1809 | I22: =$K$5-C22 -> 55.8637 | J22: =$K$5-D22 -> 54.9121 | K22: =$K$5-E22 -> 54.4363 | L22: =$K$6-F22 -> 65.7614 | M22: =$K$6-G22 -> 64.1754 | O22: Nivel de señal en Toma(dBuV) | P22: FM | Q22: DAB | R22: TDT | T22: FI | V22: Nivel de señal en Toma(dBuV)
A23: 8A-Dorm.Ppal. | B23: =B$114+B$128+'1.Distancias'!$B18*'2.Red'!$B$9+'2.Red'!$G$17 -> 43.4964 | C23: =C$114+C$128+'1.Distancias'!$B18*'2.Red'!$B$10+'2.Red'!$H$17 -> 43.7952 | D23: =D$114+D$128+'1.Distancias'!$B18*'2.Red'!$B$11+'2.Red'!$I$17 -> 44.6916 | E23: =E$114+E$128+'1.Distancias'!$B18*'2.Red'!$B$13+'2.Red'!$I$17 -> 45.1398 | F23: =F$114+F$128+'1.Distancias'!$B18*'2.Red'!$B$14+'2.Red'!$J$17 -> 41.1386 | G23: =G$114+G$128+'1.Distancias'!$B18*'2.Red'!$B$17+'2.Red'!$J$17 -> 42.6326 | H23: =$K$5-B23 -> 56.2361 | I23: =$K$5-C23 -> 55.9373 | J23: =$K$5-D23 -> 55.0409 | K23: =$K$5-E23 -> 54.5927 | L23: =$K$6-F23 -> 65.9362 | M23: =$K$6-G23 -> 64.4422 | P23: ( f = 100 MHz ) | Q23: ( f = 200 MHz ) | R23: ( f = 470 MHz ) | S23: ( f = 862 MHz ) | T23: ( f = 950 MHz ) | U23: ( f = 2150 MHz )
A24: 8A-Cocina | B24: =B$114+B$128+'1.Distancias'!$B19*'2.Red'!$B$9+'2.Red'!$G$17 -> 43.2204 | C24: =C$114+C$128+'1.Distancias'!$B19*'2.Red'!$B$10+'2.Red'!$H$17 -> 43.4272 | D24: =D$114+D$128+'1.Distancias'!$B19*'2.Red'!$B$11+'2.Red'!$I$17 -> 44.0476 | E24: =E$114+E$128+'1.Distancias'!$B19*'2.Red'!$B$13+'2.Red'!$I$17 -> 44.3578 | F24: =F$114+F$128+'1.Distancias'!$B19*'2.Red'!$B$14+'2.Red'!$J$17 -> 40.2646 | G24: =G$114+G$128+'1.Distancias'!$B19*'2.Red'!$B$17+'2.Red'!$J$17 -> 41.2986 | H24: =$K$5-B24 -> 56.5121 | I24: =$K$5-C24 -> 56.3053 | J24: =$K$5-D24 -> 55.6849 | K24: =$K$5-E24 -> 55.3747 | L24: =$K$6-F24 -> 66.8102 | M24: =$K$6-G24 -> 65.7762 | O24: Señal Toma mejor | P24: =H98 -> 53.2953 | Q24: =I98 -> 52.6829 | R24: =J98 -> 50.5057 | S24: =K98 -> 49.4071 | T24: =L98 -> 57.317 | U24: =M98 -> 53.655 | V24: Señal Toma mejor
A25: 8A-Salón | B25: =B$114+B$128+'1.Distancias'!$B20*'2.Red'!$B$9+'2.Red'!$G$17 -> 43.2714 | C25: =C$114+C$128+'1.Distancias'!$B20*'2.Red'!$B$10+'2.Red'!$H$17 -> 43.4952 | D25: =D$114+D$128+'1.Distancias'!$B20*'2.Red'!$B$11+'2.Red'!$I$17 -> 44.1666 | E25: =E$114+E$128+'1.Distancias'!$B20*'2.Red'!$B$13+'2.Red'!$I$17 -> 44.5023 | F25: =F$114+F$128+'1.Distancias'!$B20*'2.Red'!$B$14+'2.Red'!$J$17 -> 40.4261 | G25: =G$114+G$128+'1.Distancias'!$B20*'2.Red'!$B$17+'2.Red'!$J$17 -> 41.5451 | H25: =$K$5-B25 -> 56.4611 | I25: =$K$5-C25 -> 56.2373 | J25: =$K$5-D25 -> 55.5659 | K25: =$K$5-E25 -> 55.2302 | L25: =$K$6-F25 -> 66.6487 | M25: =$K$6-G25 -> 65.5297 | O25: Seña Toma peor | P25: =H97 -> 58.0673 | Q25: =I97 -> 57.8789 | R25: =J97 -> 57.3137 | S25: =K97 -> 57.0311 | T25: =L97 -> 68.985 | U25: =M97 -> 68.043 | V25: Seña Toma peor
A26: 7B-Dorm.3 | B26: =B$115+B$129+'1.Distancias'!$B21*'2.Red'!$B$9+'2.Red'!$G$17 -> 45.1752 | C26: =C$115+C$129+'1.Distancias'!$B21*'2.Red'!$B$10+'2.Red'!$H$17 -> 45.5336 | D26: =D$115+D$129+'1.Distancias'!$B21*'2.Red'!$B$11+'2.Red'!$I$17 -> 46.6088 | E26: =E$115+E$129+'1.Distancias'!$B21*'2.Red'!$B$13+'2.Red'!$I$17 -> 47.1464 | F26: =F$115+F$129+'1.Distancias'!$B21*'2.Red'!$B$14+'2.Red'!$J$17 -> 43.7048 | G26: =G$115+G$129+'1.Distancias'!$B21*'2.Red'!$B$17+'2.Red'!$J$17 -> 45.4968 | H26: =$K$5-B26 -> 54.5573 | I26: =$K$5-C26 -> 54.1989 | J26: =$K$5-D26 -> 53.1237 | K26: =$K$5-E26 -> 52.5861 | L26: =$K$6-F26 -> 63.37 | M26: =$K$6-G26 -> 61.578 | O26: Desequilibrio(dB) | P26: N/A | Q26: N/A | R26: =R25-R24 -> 6.808 | S26: =S25-S24 -> 7.624 | T26: N/A | U26: N/A | V26: Desequilibrio(dB)
A27: 7B-Dorm.2 | B27: =B$115+B$129+'1.Distancias'!$B22*'2.Red'!$B$9+'2.Red'!$G$17 -> 45.3972 | C27: =C$115+C$129+'1.Distancias'!$B22*'2.Red'!$B$10+'2.Red'!$H$17 -> 45.8296 | D27: =D$115+D$129+'1.Distancias'!$B22*'2.Red'!$B$11+'2.Red'!$I$17 -> 47.1268 | E27: =E$115+E$129+'1.Distancias'!$B22*'2.Red'!$B$13+'2.Red'!$I$17 -> 47.7754 | F27: =F$115+F$129+'1.Distancias'!$B22*'2.Red'!$B$14+'2.Red'!$J$17 -> 44.4078 | G27: =G$115+G$129+'1.Distancias'!$B22*'2.Red'!$B$17+'2.Red'!$J$17 -> 46.5698 | H27: =$K$5-B27 -> 54.3353 | I27: =$K$5-C27 -> 53.9029 | J27: =$K$5-D27 -> 52.6057 | K27: =$K$5-E27 -> 51.9571 | L27: =$K$6-F27 -> 62.667 | M27: =$K$6-G27 -> 60.505 | O27: Desequilibrio(dB) <= 12dB | P27: N/A | Q27: N/A | R27: =IF(R26<=12,"SI","NO") -> SI | S27: =IF(S26<=12,"SI","NO") -> SI | T27: N/A | U27: N/A | V27: Desequilibrio(dB) <= 12dB
A28: 7B-Dorm.Ppal. | B28: =B$115+B$129+'1.Distancias'!$B23*'2.Red'!$B$9+'2.Red'!$G$17 -> 45.342 | C28: =C$115+C$129+'1.Distancias'!$B23*'2.Red'!$B$10+'2.Red'!$H$17 -> 45.756 | D28: =D$115+D$129+'1.Distancias'!$B23*'2.Red'!$B$11+'2.Red'!$I$17 -> 46.998 | E28: =E$115+E$129+'1.Distancias'!$B23*'2.Red'!$B$13+'2.Red'!$I$17 -> 47.619 | F28: =F$115+F$129+'1.Distancias'!$B23*'2.Red'!$B$14+'2.Red'!$J$17 -> 44.233 | G28: =G$115+G$129+'1.Distancias'!$B23*'2.Red'!$B$17+'2.Red'!$J$17 -> 46.303 | H28: =$K$5-B28 -> 54.3905 | I28: =$K$5-C28 -> 53.9765 | J28: =$K$5-D28 -> 52.7345 | K28: =$K$5-E28 -> 52.1135 | L28: =$K$6-F28 -> 62.8418 | M28: =$K$6-G28 -> 60.7718
A29: 7B-Cocina | B29: =B$115+B$129+'1.Distancias'!$B24*'2.Red'!$B$9+'2.Red'!$G$17 -> 45.066 | C29: =C$115+C$129+'1.Distancias'!$B24*'2.Red'!$B$10+'2.Red'!$H$17 -> 45.388 | D29: =D$115+D$129+'1.Distancias'!$B24*'2.Red'!$B$11+'2.Red'!$I$17 -> 46.354 | E29: =E$115+E$129+'1.Distancias'!$B24*'2.Red'!$B$13+'2.Red'!$I$17 -> 46.837 | F29: =F$115+F$129+'1.Distancias'!$B24*'2.Red'!$B$14+'2.Red'!$J$17 -> 43.359 | G29: =G$115+G$129+'1.Distancias'!$B24*'2.Red'!$B$17+'2.Red'!$J$17 -> 44.969 | H29: =$K$5-B29 -> 54.6665 | I29: =$K$5-C29 -> 54.3445 | J29: =$K$5-D29 -> 53.3785 | K29: =$K$5-E29 -> 52.8955 | L29: =$K$6-F29 -> 63.7158 | M29: =$K$6-G29 -> 62.1058 | O29: Respuesta Amplitud-Frecuencia o rizado (RAF) en toma peor(dBuV) | P29: TERR | T29: FI | V29: Respuesta Amplitud-Frecuencia o rizado (RAF) en toma peor(dBuV)
A30: 7B-Salón | B30: =B$115+B$129+'1.Distancias'!$B25*'2.Red'!$B$9+'2.Red'!$G$17 -> 45.117 | C30: =C$115+C$129+'1.Distancias'!$B25*'2.Red'!$B$10+'2.Red'!$H$17 -> 45.456 | D30: =D$115+D$129+'1.Distancias'!$B25*'2.Red'!$B$11+'2.Red'!$I$17 -> 46.473 | E30: =E$115+E$129+'1.Distancias'!$B25*'2.Red'!$B$13+'2.Red'!$I$17 -> 46.9815 | F30: =F$115+F$129+'1.Distancias'!$B25*'2.Red'!$B$14+'2.Red'!$J$17 -> 43.5205 | G30: =G$115+G$129+'1.Distancias'!$B25*'2.Red'!$B$17+'2.Red'!$J$17 -> 45.2155 | H30: =$K$5-B30 -> 54.6155 | I30: =$K$5-C30 -> 54.2765 | J30: =$K$5-D30 -> 53.2595 | K30: =$K$5-E30 -> 52.751 | L30: =$K$6-F30 -> 63.5543 | M30: =$K$6-G30 -> 61.8593 | P30: ( f = 15 MHz ) | R30: ( f = 862 MHz ) | T30: ( f = 950 MHz ) | U30: ( f = 2150 MHz ) | Y30: Rizado(dB)
A31: 7A-Dorm.3 | B31: =B$115+B$130+'1.Distancias'!$B26*'2.Red'!$B$9+'2.Red'!$G$17 -> 45.0096 | C31: =C$115+C$130+'1.Distancias'!$B26*'2.Red'!$B$10+'2.Red'!$H$17 -> 45.3128 | D31: =D$115+D$130+'1.Distancias'!$B26*'2.Red'!$B$11+'2.Red'!$I$17 -> 46.2224 | E31: =E$115+E$130+'1.Distancias'!$B26*'2.Red'!$B$13+'2.Red'!$I$17 -> 46.6772 | F31: =F$115+F$130+'1.Distancias'!$B26*'2.Red'!$B$14+'2.Red'!$J$17 -> 43.1804 | G31: =G$115+G$130+'1.Distancias'!$B26*'2.Red'!$B$17+'2.Red'!$J$17 -> 44.6964 | H31: =$K$5-B31 -> 54.7229 | I31: =$K$5-C31 -> 54.4197 | J31: =$K$5-D31 -> 53.5101 | K31: =$K$5-E31 -> 53.0553 | L31: =$K$6-F31 -> 63.8944 | M31: =$K$6-G31 -> 62.3784 | O31: Rcable(dB) = L * (Afmax-Afmin) | P31: =36.63*('2.Red'!B13-'2.Red'!B8) -> 5.1282 | T31: =36.63*('2.Red'!B17-'2.Red'!B14) -> 3.663 | V31: Rcable(dB) = L * (Afmax-Afmin) | X31: Mezclador | Y31: 0.5
A32: 7A-Dorm.2 | B32: =B$115+B$130+'1.Distancias'!$B27*'2.Red'!$B$9+'2.Red'!$G$17 -> 45.2316 | C32: =C$115+C$130+'1.Distancias'!$B27*'2.Red'!$B$10+'2.Red'!$H$17 -> 45.6088 | D32: =D$115+D$130+'1.Distancias'!$B27*'2.Red'!$B$11+'2.Red'!$I$17 -> 46.7404 | E32: =E$115+E$130+'1.Distancias'!$B27*'2.Red'!$B$13+'2.Red'!$I$17 -> 47.3062 | F32: =F$115+F$130+'1.Distancias'!$B27*'2.Red'!$B$14+'2.Red'!$J$17 -> 43.8834 | G32: =G$115+G$130+'1.Distancias'!$B27*'2.Red'!$B$17+'2.Red'!$J$17 -> 45.7694 | H32: =$K$5-B32 -> 54.5009 | I32: =$K$5-C32 -> 54.1237 | J32: =$K$5-D32 -> 52.9921 | K32: =$K$5-E32 -> 52.4263 | L32: =$K$6-F32 -> 63.1914 | M32: =$K$6-G32 -> 61.3054 | O32: Relementos(dB) = Sum(2*ti) | P32: =2*($Y$31+8*$Y$32+$Y$33+$Y$34) -> 7.3 | T32: =2*($Y$31+8*$Y$32+$Y$33+$Y$34) -> 7.3 | V32: Relementos(dB) = Sum(2*ti) | X32: Derivador | Y32: 0.3
A33: 7A-Dorm.Ppal. | B33: =B$115+B$130+'1.Distancias'!$B28*'2.Red'!$B$9+'2.Red'!$G$17 -> 45.1764 | C33: =C$115+C$130+'1.Distancias'!$B28*'2.Red'!$B$10+'2.Red'!$H$17 -> 45.5352 | D33: =D$115+D$130+'1.Distancias'!$B28*'2.Red'!$B$11+'2.Red'!$I$17 -> 46.6116 | E33: =E$115+E$130+'1.Distancias'!$B28*'2.Red'!$B$13+'2.Red'!$I$17 -> 47.1498 | F33: =F$115+F$130+'1.Distancias'!$B28*'2.Red'!$B$14+'2.Red'!$J$17 -> 43.7086 | G33: =G$115+G$130+'1.Distancias'!$B28*'2.Red'!$B$17+'2.Red'!$J$17 -> 45.5026 | H33: =$K$5-B33 -> 54.5561 | I33: =$K$5-C33 -> 54.1973 | J33: =$K$5-D33 -> 53.1209 | K33: =$K$5-E33 -> 52.5827 | L33: =$K$6-F33 -> 63.3662 | M33: =$K$6-G33 -> 61.5722 | O33: Rizado total toma peor | P33: =SUM(P31:P32) -> 12.4282 | T33: =SUM(T31:U32) -> 10.963 | V33: Rizado total toma peor | X33: PAU | Y33: 0.25
A34: 7A-Cocina | B34: =B$115+B$130+'1.Distancias'!$B29*'2.Red'!$B$9+'2.Red'!$G$17 -> 44.9004 | C34: =C$115+C$130+'1.Distancias'!$B29*'2.Red'!$B$10+'2.Red'!$H$17 -> 45.1672 | D34: =D$115+D$130+'1.Distancias'!$B29*'2.Red'!$B$11+'2.Red'!$I$17 -> 45.9676 | E34: =E$115+E$130+'1.Distancias'!$B29*'2.Red'!$B$13+'2.Red'!$I$17 -> 46.3678 | F34: =F$115+F$130+'1.Distancias'!$B29*'2.Red'!$B$14+'2.Red'!$J$17 -> 42.8346 | G34: =G$115+G$130+'1.Distancias'!$B29*'2.Red'!$B$17+'2.Red'!$J$17 -> 44.1686 | H34: =$K$5-B34 -> 54.8321 | I34: =$K$5-C34 -> 54.5653 | J34: =$K$5-D34 -> 53.7649 | K34: =$K$5-E34 -> 53.3647 | L34: =$K$6-F34 -> 64.2402 | M34: =$K$6-G34 -> 62.9062 | O34: RAF <= 16dB | P34: =IF(P33<=16,"SI","NO") -> SI | T34: =IF(T33<=16,"SI","NO") -> SI | V34: RAF <= 16dB | X34: BAT | Y34: 0.5
A35: 7A-Salón | B35: =B$115+B$130+'1.Distancias'!$B30*'2.Red'!$B$9+'2.Red'!$G$17 -> 44.9514 | C35: =C$115+C$130+'1.Distancias'!$B30*'2.Red'!$B$10+'2.Red'!$H$17 -> 45.2352 | D35: =D$115+D$130+'1.Distancias'!$B30*'2.Red'!$B$11+'2.Red'!$I$17 -> 46.0866 | E35: =E$115+E$130+'1.Distancias'!$B30*'2.Red'!$B$13+'2.Red'!$I$17 -> 46.5123 | F35: =F$115+F$130+'1.Distancias'!$B30*'2.Red'!$B$14+'2.Red'!$J$17 -> 42.9961 | G35: =G$115+G$130+'1.Distancias'!$B30*'2.Red'!$B$17+'2.Red'!$J$17 -> 44.4151 | H35: =$K$5-B35 -> 54.7811 | I35: =$K$5-C35 -> 54.4973 | J35: =$K$5-D35 -> 53.6459 | K35: =$K$5-E35 -> 53.2202 | L35: =$K$6-F35 -> 64.0787 | M35: =$K$6-G35 -> 62.6597
A36: 6B-Dorm.3 | B36: =B$116+B$131+'1.Distancias'!$B31*'2.Red'!$B$9+'2.Red'!$G$17 -> 42.8552 | C36: =C$116+C$131+'1.Distancias'!$B31*'2.Red'!$B$10+'2.Red'!$H$17 -> 43.2736 | D36: =D$116+D$131+'1.Distancias'!$B31*'2.Red'!$B$11+'2.Red'!$I$17 -> 44.5288 | E36: =E$116+E$131+'1.Distancias'!$B31*'2.Red'!$B$13+'2.Red'!$I$17 -> 45.1564 | F36: =F$116+F$131+'1.Distancias'!$B31*'2.Red'!$B$14+'2.Red'!$J$17 -> 42.2748 | G36: =G$116+G$131+'1.Distancias'!$B31*'2.Red'!$B$17+'2.Red'!$J$17 -> 44.3668 | H36: =$K$5-B36 -> 56.8773 | I36: =$K$5-C36 -> 56.4589 | J36: =$K$5-D36 -> 55.2037 | K36: =$K$5-E36 -> 54.5761 | L36: =$K$6-F36 -> 64.8 | M36: =$K$6-G36 -> 62.708 | O36: Relación S/I(dB) | P36: FM | Q36: DAB | R36: TDT | T36: FI | V36: Relación S/I(dB)
A37: 6B-Dorm.2 | B37: =B$116+B$131+'1.Distancias'!$B32*'2.Red'!$B$9+'2.Red'!$G$17 -> 43.0772 | C37: =C$116+C$131+'1.Distancias'!$B32*'2.Red'!$B$10+'2.Red'!$H$17 -> 43.5696 | D37: =D$116+D$131+'1.Distancias'!$B32*'2.Red'!$B$11+'2.Red'!$I$17 -> 45.0468 | E37: =E$116+E$131+'1.Distancias'!$B32*'2.Red'!$B$13+'2.Red'!$I$17 -> 45.7854 | F37: =F$116+F$131+'1.Distancias'!$B32*'2.Red'!$B$14+'2.Red'!$J$17 -> 42.9778 | G37: =G$116+G$131+'1.Distancias'!$B32*'2.Red'!$B$17+'2.Red'!$J$17 -> 45.4398 | H37: =$K$5-B37 -> 56.6553 | I37: =$K$5-C37 -> 56.1629 | J37: =$K$5-D37 -> 54.6857 | K37: =$K$5-E37 -> 53.9471 | L37: =$K$6-F37 -> 64.097 | M37: =$K$6-G37 -> 61.635 | P37: ( f = 100 MHz ) | Q37: ( f = 200 MHz ) | R37: ( f = 470 MHz ) | S37: ( f = 862 MHz ) | T37: ( f = 950 MHz ) | U37: ( f = 2150 MHz )
A38: 6B-Dorm.Ppal. | B38: =B$116+B$131+'1.Distancias'!$B33*'2.Red'!$B$9+'2.Red'!$G$17 -> 43.022 | C38: =C$116+C$131+'1.Distancias'!$B33*'2.Red'!$B$10+'2.Red'!$H$17 -> 43.496 | D38: =D$116+D$131+'1.Distancias'!$B33*'2.Red'!$B$11+'2.Red'!$I$17 -> 44.918 | E38: =E$116+E$131+'1.Distancias'!$B33*'2.Red'!$B$13+'2.Red'!$I$17 -> 45.629 | F38: =F$116+F$131+'1.Distancias'!$B33*'2.Red'!$B$14+'2.Red'!$J$17 -> 42.803 | G38: =G$116+G$131+'1.Distancias'!$B33*'2.Red'!$B$17+'2.Red'!$J$17 -> 45.173 | H38: =$K$5-B38 -> 56.7105 | I38: =$K$5-C38 -> 56.2365 | J38: =$K$5-D38 -> 54.8145 | K38: =$K$5-E38 -> 54.1035 | L38: =$K$6-F38 -> 64.2718 | M38: =$K$6-G38 -> 61.9018 | O38: S/IM3ref(dB) | P38: 56 | Q38: 56 | R38: 35 | T38: 35 | V38: S/IM3ref(dB)
A39: 6B-Cocina | B39: =B$116+B$131+'1.Distancias'!$B34*'2.Red'!$B$9+'2.Red'!$G$17 -> 42.746 | C39: =C$116+C$131+'1.Distancias'!$B34*'2.Red'!$B$10+'2.Red'!$H$17 -> 43.128 | D39: =D$116+D$131+'1.Distancias'!$B34*'2.Red'!$B$11+'2.Red'!$I$17 -> 44.274 | E39: =E$116+E$131+'1.Distancias'!$B34*'2.Red'!$B$13+'2.Red'!$I$17 -> 44.847 | F39: =F$116+F$131+'1.Distancias'!$B34*'2.Red'!$B$14+'2.Red'!$J$17 -> 41.929 | G39: =G$116+G$131+'1.Distancias'!$B34*'2.Red'!$B$17+'2.Red'!$J$17 -> 43.839 | H39: =$K$5-B39 -> 56.9865 | I39: =$K$5-C39 -> 56.6045 | J39: =$K$5-D39 -> 55.4585 | K39: =$K$5-E39 -> 54.8855 | L39: =$K$6-F39 -> 65.1458 | M39: =$K$6-G39 -> 63.2358 | O39: Sref | P39: 120 | Q39: 113 | R39: 118 | T39: 124 | V39: Sref
A40: 6B-Salón | B40: =B$116+B$131+'1.Distancias'!$B35*'2.Red'!$B$9+'2.Red'!$G$17 -> 42.797 | C40: =C$116+C$131+'1.Distancias'!$B35*'2.Red'!$B$10+'2.Red'!$H$17 -> 43.196 | D40: =D$116+D$131+'1.Distancias'!$B35*'2.Red'!$B$11+'2.Red'!$I$17 -> 44.393 | E40: =E$116+E$131+'1.Distancias'!$B35*'2.Red'!$B$13+'2.Red'!$I$17 -> 44.9915 | F40: =F$116+F$131+'1.Distancias'!$B35*'2.Red'!$B$14+'2.Red'!$J$17 -> 42.0905 | G40: =G$116+G$131+'1.Distancias'!$B35*'2.Red'!$B$17+'2.Red'!$J$17 -> 44.0855 | H40: =$K$5-B40 -> 56.9355 | I40: =$K$5-C40 -> 56.5365 | J40: =$K$5-D40 -> 55.3395 | K40: =$K$5-E40 -> 54.741 | L40: =$K$6-F40 -> 64.9843 | M40: =$K$6-G40 -> 62.9893 | O40: StomaPeor | P40: =H102+P12+'2.Red'!D17 -> 87.9372 | Q40: =I102+Q12+'2.Red'!D17 -> 78.5496 | R40: =J102+S12+'2.Red'!D17 -> 98.8254 | T40: =L102+U12+'2.Red'!E17 -> 102.2198 | V40: StomaPeor
A41: 6A-Dorm.3 | B41: =B$116+B$132+'1.Distancias'!$B36*'2.Red'!$B$9+'2.Red'!$G$17 -> 42.6896 | C41: =C$116+C$132+'1.Distancias'!$B36*'2.Red'!$B$10+'2.Red'!$H$17 -> 43.0528 | D41: =D$116+D$132+'1.Distancias'!$B36*'2.Red'!$B$11+'2.Red'!$I$17 -> 44.1424 | E41: =E$116+E$132+'1.Distancias'!$B36*'2.Red'!$B$13+'2.Red'!$I$17 -> 44.6872 | F41: =F$116+F$132+'1.Distancias'!$B36*'2.Red'!$B$14+'2.Red'!$J$17 -> 41.7504 | G41: =G$116+G$132+'1.Distancias'!$B36*'2.Red'!$B$17+'2.Red'!$J$17 -> 43.5664 | H41: =$K$5-B41 -> 57.0429 | I41: =$K$5-C41 -> 56.6797 | J41: =$K$5-D41 -> 55.5901 | K41: =$K$5-E41 -> 55.0453 | L41: =$K$6-F41 -> 65.3244 | M41: =$K$6-G41 -> 63.5084 | O41: S/IM3(dB) = S/IM3ref(dB)+2*(Sref-Stomapeor) | P41: =P38+2*(P39-P40) -> 120.1256 | Q41: =Q38+2*(Q39-Q40) -> 124.9008 | R41: =R38+2*(R39-R40) -> 73.3492 | T41: =T38+2*(T39-T40) -> 78.5604 | V41: S/IM3(dB) = S/IM3ref(dB)+2*(Sref-Stomapeor)
A42: 6A-Dorm.2 | B42: =B$116+B$132+'1.Distancias'!$B37*'2.Red'!$B$9+'2.Red'!$G$17 -> 42.9116 | C42: =C$116+C$132+'1.Distancias'!$B37*'2.Red'!$B$10+'2.Red'!$H$17 -> 43.3488 | D42: =D$116+D$132+'1.Distancias'!$B37*'2.Red'!$B$11+'2.Red'!$I$17 -> 44.6604 | E42: =E$116+E$132+'1.Distancias'!$B37*'2.Red'!$B$13+'2.Red'!$I$17 -> 45.3162 | F42: =F$116+F$132+'1.Distancias'!$B37*'2.Red'!$B$14+'2.Red'!$J$17 -> 42.4534 | G42: =G$116+G$132+'1.Distancias'!$B37*'2.Red'!$B$17+'2.Red'!$J$17 -> 44.6394 | H42: =$K$5-B42 -> 56.8209 | I42: =$K$5-C42 -> 56.3837 | J42: =$K$5-D42 -> 55.0721 | K42: =$K$5-E42 -> 54.4163 | L42: =$K$6-F42 -> 64.6214 | M42: =$K$6-G42 -> 62.4354 | O42: S/IM3(dB)requerido RD | P42: 27 | Q42: 18 | R42: 30 | T42: 18 | V42: S/IM3(dB)requerido RD
A43: 6A-Dorm.Ppal. | B43: =B$116+B$132+'1.Distancias'!$B38*'2.Red'!$B$9+'2.Red'!$G$17 -> 42.8564 | C43: =C$116+C$132+'1.Distancias'!$B38*'2.Red'!$B$10+'2.Red'!$H$17 -> 43.2752 | D43: =D$116+D$132+'1.Distancias'!$B38*'2.Red'!$B$11+'2.Red'!$I$17 -> 44.5316 | E43: =E$116+E$132+'1.Distancias'!$B38*'2.Red'!$B$13+'2.Red'!$I$17 -> 45.1598 | F43: =F$116+F$132+'1.Distancias'!$B38*'2.Red'!$B$14+'2.Red'!$J$17 -> 42.2786 | G43: =G$116+G$132+'1.Distancias'!$B38*'2.Red'!$B$17+'2.Red'!$J$17 -> 44.3726 | H43: =$K$5-B43 -> 56.8761 | I43: =$K$5-C43 -> 56.4573 | J43: =$K$5-D43 -> 55.2009 | K43: =$K$5-E43 -> 54.5727 | L43: =$K$6-F43 -> 64.7962 | M43: =$K$6-G43 -> 62.7022 | O43: Cumple RD? | P43: =IF(P41>=P42,"SI","NO") -> SI | Q43: =IF(Q41>=Q42,"SI","NO") -> SI | R43: =IF(R41>=R42,"SI","NO") -> SI | T43: =IF(T41>=T42,"SI","NO") -> SI | V43: Cumple RD?
...

Sheet 4.Cabecera
A1: Se exponen aquí las características más relevantes para el diseño de la cabecera de RTV y Satélite.
A6: ANTENAS
B7: FM | C7: DAB | D7: TDT* | E7: SAT
A8: Ganancia (dBi) | B8: 1 | C8: 8 | D8: 17 | E8: 35.5 | G8: *Modo BOSS on 42dBi Modo off 17dBi
A10: LNB | D10: AMPLIFICADORES MONOCANALES
A11: Ganancia (dB) | B11: 60 | E11: FM | F11: DAB | G11: TDT | H11: SAT | J11: FUENTE ALIMENTACIÓN
A12: Figura de ruido (dB) | B12: 0.3 | D12: Ganancia MAX (dB) | E12: 40 | F12: 48 | G12: 50 | H12: 50 | J12: Voltaje de salida (V) | K12: 24
A13: Consumo: I_MAX (mA) | B13: 110 | D13: Figura de ruido (dB) | E13: 10 | F13: 10 | G13: 10 | H13: 10 | J13: Corriente máx entrada (mA) | K13: 2500
D14: Consumo: I_MAX (mA) | E14: 220 | F14: 220 | G14: 95 | H14: 100
J15: Sum(I_MAX Amplificador)(mA) | K15: =SUM(E14,F14, 10*G14) -> 1390
J16: Corriente máx entrada Fuente Al (mA) | K16: 2500
J17: Redimiento(%) | K17: =K15/K16 -> 0.556 | L17: <=75%

Sheet 5.CalculoCab
A1: Se comprueba aquí si la cabecera RTV (no SAT) está bien configurada. | Q1: Info canales | R1: https://televisiondigital.mineco.gob.es/2DD-5G/Paginas/Que-tengo-que-hacer.aspx
R2: https://www.antenadigital.es/tdt/malaga.php
D7: TDT | O7: Denominación | P7: Tipo | Q7: Canal | R7: Frecuencia central (MHz) | S7: Señal de entrada (dBμV) Sent(dBμV) = 3+20logf(MHz)
B8: FM | C8: DAB | D8: C23 | E8: C24 | F8: C26 | G8: C33 | H8: C34 | I8: C35 | J8: C39 | K8: C42 | L8: C44 | M8: C47 | O8: MAUT(TL05MA) | P8: LOCAL | Q8: 23 | R8: 490 | S8: =ROUND(3+20*log($R8),2) -> 56.8
A9: Intensidad de campo (dBuV/m) | B9: =S18 -> 74 | C9: =S19 -> 58 | D9: =S8 -> 56.8 | E9: =S9 -> 56.94 | F9: =S10 -> 57.22 | G9: =S11 -> 58.12 | H9: =S12 -> 58.24 | I9: =S13 -> 58.36 | J9: =S14 -> 58.82 | K9: =S15 -> 59.15 | L9: =S16 -> 59.36 | M9: =S17 -> 59.68 | N9: TDT = 3+20logf(MHz) Intensidad de campo mínimo por RD-346 | O9: RGE1-AND | P9: ESTATAL | Q9: 24 | R9: 498 | S9: =ROUND(3+20*log($R9),2) -> 56.94
A10: Ganancia antena (dBi) | B10: ='4.Cabecera'!$B$8 -> 1 | C10: ='4.Cabecera'!$C$8 -> 8 | D10: ='4.Cabecera'!$D$8 -> 17 | E10: ='4.Cabecera'!$D$8 -> 17 | F10: ='4.Cabecera'!$D$8 -> 17 | G10: ='4.Cabecera'!$D$8 -> 17 | H10: ='4.Cabecera'!$D$8 -> 17 | I10: ='4.Cabecera'!$D$8 -> 17 | J10: ='4.Cabecera'!$D$8 -> 17 | K10: ='4.Cabecera'!$D$8 -> 17 | ... M10: ='4.Cabecera'!$D$8 -> 17 | O10: TDTEMP4K | P10: ESTATAL | Q10: 26 | R10: 514 | S10: =ROUND(3+20*log($R10),2) -> 57.22
A11: Señal a la salida de la antena (dBuV) | B11: =ROUND(B9+B10-20*log(100)+32,2) -> 67 | C11: =ROUND(C9+C10-20*log(200)+32,2) -> 51.98 | D11: =ROUND(D9+D10-20*log(R8)+32,2) -> 52 | E11: =ROUND(E9+E10-20*log(R9)+32,2) -> 52 | F11: =ROUND(F9+F10-20*log(R10)+32,2) -> 52 | G11: =ROUND(G9+G10-20*log(R11)+32,2) -> 52 | H11: =ROUND(H9+H10-20*log(R12)+32,2) -> 52 | I11: =ROUND(I9+I10-20*log(R13)+32,2) -> 52 | J11: =ROUND(J9+J10-20*log(R14)+32,2) -> 52 | K11: =ROUND(K9+K10-20*log(R15)+32,2) -> 52 | L11: =ROUND(L9+L10-20*log(R16)+32,2) -> 52 | M11: =ROUND(M9+M10-20*log(R17)+32,2) -> 52 | N11: S(dBuV) = E(dBuV/m) + G(dB) - 20log(f) + 32 | O11: RGE2 | P11: ESTATAL | Q11: 33 | R11: 570 | S11: =ROUND(3+20*log($R11),2) -> 58.12
A12: Señal entrada amplif. (dBuV) | B12: =B11 -> 67 | C12: =C11 -> 51.98 | D12: =D11 -> 52 | E12: =E11 -> 52 | F12: =F11 -> 52 | G12: =G11 -> 52 | H12: =H11 -> 52 | I12: =I11 -> 52 | ... M12: =M11 -> 52 | N12: Sent = Ssal no se consideran pérdidas del cable | O12: MAUT-AND | P12: AUTONÓMICO | Q12: 34 | R12: 578 | S12: =ROUND(3+20*log($R12),2) -> 58.24
A13: Señal salida cabecera (dBuV) | B13: ='3.CalculoRedRTV-SAT'!$K$5 -> 99.7325 | C13: ='3.CalculoRedRTV-SAT'!$K$5 -> 99.7325 | D13: ='3.CalculoRedRTV-SAT'!$K$5 -> 99.7325 | E13: ='3.CalculoRedRTV-SAT'!$K$5 -> 99.7325 | F13: ='3.CalculoRedRTV-SAT'!$K$5 -> 99.7325 | G13: ='3.CalculoRedRTV-SAT'!$K$5 -> 99.7325 | H13: ='3.CalculoRedRTV-SAT'!$K$5 -> 99.7325 | I13: ='3.CalculoRedRTV-SAT'!$K$5 -> 99.7325 | ... M13: ='3.CalculoRedRTV-SAT'!$K$5 -> 99.7325 | N13: Valor estimado necesario | O13: MPE4 | P13: ESTATAL | Q13: 35 | R13: 586 | S13: =ROUND(3+20*log($R13),2) -> 58.36
A14: Ganancia exigida al amplif. (dB) | B14: =B13-B12 -> 32.7325 | C14: =C13-C12 -> 47.7525 | D14: =D13-D12 -> 47.7325 | E14: =E13-E12 -> 47.7325 | F14: =F13-F12 -> 47.7325 | G14: =G13-G12 -> 47.7325 | H14: =H13-H12 -> 47.7325 | I14: =I13-I12 -> 47.7325 | ... M14: =M13-M12 -> 47.7325 | N14: G(dB) = Ssal(dBuV/m) - Sent(dBuV/m) | O14: MPE1 | P14: ESTATAL | Q14: 39 | R14: 618 | S14: =ROUND(3+20*log($R14),2) -> 58.82
A15: ¿Amplificador válido? | B15: =IF(B14>='4.Cabecera'!$E$12,"NO","SI") -> SI | C15: =IF(C14>='4.Cabecera'!$F$12,"NO","SI") -> SI | D15: =IF(D14>='4.Cabecera'!$G$12,"NO","SI") -> SI | E15: =IF(E14>='4.Cabecera'!$G$12,"NO","SI") -> SI | F15: =IF(F14>='4.Cabecera'!$G$12,"NO","SI") -> SI | G15: =IF(G14>='4.Cabecera'!$G$12,"NO","SI") -> SI | H15: =IF(H14>='4.Cabecera'!$G$12,"NO","SI") -> SI | I15: =IF(I14>='4.Cabecera'!$G$12,"NO","SI") -> SI | J15: =IF(J14>='4.Cabecera'!$G$12,"NO","SI") -> SI | K15: =IF(K14>='4.Cabecera'!$G$12,"NO","SI") -> SI | ... M15: =IF(M14>='4.Cabecera'!$G$12,"NO","SI") -> SI | N15: Ganancia necesaria < Ganancia máxima amplificador | O15: MPE2 | P15: ESTATAL | Q15: 42 | R15: 642 | S15: =ROUND(3+20*log($R15),2) -> 59.15
O16: MPE3 | P16: ESTATAL | Q16: 44 | R16: 658 | S16: =ROUND(3+20*log($R16),2) -> 59.36
O17: MPE5 | P17: ESTATAL | Q17: 47 | R17: 682 | S17: =ROUND(3+20*log($R17),2) -> 59.68
O18: FM | P18: RADIO | Q18: Canales en la banda 87,5 a 108 MHz | S18: 74 | T18: valor típico
O19: DAB | P19: RADIO | Q19: Canales en la banda 195 a 223 MHz (canales 8-11) | S19: 58 | T19: valor típico

Sheet 8.CalculoRedFO
A1: Se exponen aquí los cálculos de la atenuación de las redes de distribución y dispersión de cable coaxial
B8: Atenuación (dB) [RegistroPpal] --> [PAU] 1310/1490 nm | C8: Atenuación (dB) [RegistroPpal] --> [PAU] 1550 nm | D8: Longitud (m) [RegistroPpal] --> [PAU] | E8: Longitud (m) [RegistroPpal] --> [TomaReserva] | G8: Atenuación (dB/(m))
B9: A(dB)PAU = 2*A(dB)ConectorSC/APC+L(m)RPPAU*A(dB)cable(nm)+A(dB)
A10: Ático | B10: =2*$H$12+D10*$H$11 -> 0.61162 | C10: =2*$I$12+D10*$I$11 -> 0.608715 | D10: =$G$18+'1.Distancias'!C6+8*$H$18 -> 29.05 | E10: =MAX(D10) -> 29.05 | H10: 1310/1490 nm | I10: 1550 nm
A11: 8ºB | B11: =2*$H$12+D11*$H$11 -> 0.6121 | C11: =2*$I$12+D11*$I$11 -> 0.609075 | D11: =$G$18+'1.Distancias'!C11+7*$H$18 -> 30.25 | E11: =MAX(D11:D12) -> 30.25 | G11: Cable FO | H11: 0.0004 | I11: 0.0003
A12: 8ºA | B12: =2*$H$12+D12*$H$11 -> 0.610996 | C12: =2*$I$12+D12*$I$11 -> 0.608247 | D12: =$G$18+'1.Distancias'!C16+7*$H$18 -> 27.49 | G12: Conector SC/APC | H12: 0.3 | I12: 0.3
A13: 7ºB | B13: =2*$H$12+D13*$H$11 -> 0.6109 | C13: =2*$I$12+D13*$I$11 -> 0.608175 | D13: =$G$18+'1.Distancias'!C21+6*$H$18 -> 27.25 | E13: =MAX(D13:D14) -> 27.25
A14: 7ºA | B14: =2*$H$12+D14*$H$11 -> 0.609796 | C14: =2*$I$12+D14*$I$11 -> 0.607347 | D14: =$G$18+'1.Distancias'!C26+6*$H$18 -> 24.49
A15: 6ºB | B15: =2*$H$12+D15*$H$11 -> 0.6097 | C15: =2*$I$12+D15*$I$11 -> 0.607275 | D15: =$G$18+'1.Distancias'!C31+5*$H$18 -> 24.25 | E15: =MAX(D15:D16) -> 24.25
A16: 6ºA | B16: =2*$H$12+D16*$H$11 -> 0.608596 | C16: =2*$I$12+D16*$I$11 -> 0.606447 | D16: =$G$18+'1.Distancias'!C36+5*$H$18 -> 21.49
A17: 5ºB | B17: =2*$H$12+D17*$H$11 -> 0.6085 | C17: =2*$I$12+D17*$I$11 -> 0.606375 | D17: =$G$18+'1.Distancias'!C41+4*$H$18 -> 21.25 | E17: =MAX(D17:D18) -> 21.25 | G17: Distancia RP --> RS1 (m) | H17: Distancia RS1 --> RS2 (m)
A18: 5ºA | B18: =2*$H$12+D18*$H$11 -> 0.607396 | C18: =2*$I$12+D18*$I$11 -> 0.605547 | D18: =$G$18+'1.Distancias'!C46+4*$H$18 -> 18.49 | G18: 3 | H18: 3
A19: 4ºB | B19: =2*$H$12+D19*$H$11 -> 0.6073 | C19: =2*$I$12+D19*$I$11 -> 0.605475 | D19: =$G$18+'1.Distancias'!C51+3*$H$18 -> 18.25 | E19: =MAX(D19:D20) -> 18.25
A20: 4ºA | B20: =2*$H$12+D20*$H$11 -> 0.606196 | C20: =2*$I$12+D20*$I$11 -> 0.604647 | D20: =$G$18+'1.Distancias'!C56+3*$H$18 -> 15.49
A21: 3ºB | B21: =2*$H$12+D21*$H$11 -> 0.6061 | C21: =2*$I$12+D21*$I$11 -> 0.604575 | D21: =$G$18+'1.Distancias'!C61+2*$H$18 -> 15.25 | E21: =MAX(D21:D22) -> 15.25
A22: 3ºA | B22: =2*$H$12+D22*$H$11 -> 0.604996 | C22: =2*$I$12+D22*$I$11 -> 0.603747 | D22: =$G$18+'1.Distancias'!C66+2*$H$18 -> 12.49
A23: 2ºB | B23: =2*$H$12+D23*$H$11 -> 0.6049 | C23: =2*$I$12+D23*$I$11 -> 0.603675 | D23: =$G$18+'1.Distancias'!C71+$H$18 -> 12.25 | E23: =MAX(D23:D24) -> 12.25
A24: 2ºA | B24: =2*$H$12+D24*$H$11 -> 0.603796 | C24: =2*$I$12+D24*$I$11 -> 0.602847 | D24: =$G$18+'1.Distancias'!C76+$H$18 -> 9.49
A25: 1ºB | B25: =2*$H$12+D25*$H$11 -> 0.6037 | C25: =2*$I$12+D25*$I$11 -> 0.602775 | D25: =$G$18+'1.Distancias'!C81 -> 9.25 | E25: =MAX(D25:D26) -> 9.25
A26: 1ºA | B26: =2*$H$12+D26*$H$11 -> 0.602596 | C26: =2*$I$12+D26*$I$11 -> 0.601947 | D26: =$G$18+'1.Distancias'!C86 -> 6.49
D27: Longitud (m) TOTAL | E27: =SUM(D10:E26) -> 510.02
D28: Toma peor | E28: 8º B
A32: Dimensionado por vivienda tipo 1º
A33: Estancia | B33: distancia | C33: BAT | D33: m cable | G33: Atenuación por vivienda tipo (dB) [PAU] --> [Toma] At(dB)[PAU->Toma]=Lcable*Atcable+Conector
A34: Dorm.3 | B34: ='1.Distancias'!B86 -> 2.36 | C34: 0 | D34: =B34*C34 -> 0 | G34: Vivienda tipo/Vivienda tipo | H34: 1º | I34: 2º - 8º | J34: Ático
A35: Dorm.2 | B35: ='1.Distancias'!B87 -> 6.75 | C35: 0 | D35: =B35*C35 -> 0 | G35: 1310nm | H35: =$H$11*$D$39+$H$12 -> 0.300848 | I35: =$H$11*$D$45+$H$12 -> 0.30068 | J35: =$H$11*$D$51+$H$12 -> 0.301748
A36: Dorm.Ppal. | B36: ='1.Distancias'!B88 -> 5.45 | C36: 0 | D36: =B36*C36 -> 0 | G36: 1490 nm | H36: =$H$11*$D$39+$H$12 -> 0.300848 | I36: =$H$11*$D$45+$H$12 -> 0.30068 | J36: =$H$11*$D$51+$H$12 -> 0.301748
A37: Cocina | B37: ='1.Distancias'!B89 -> 1.14 | C37: 0 | D37: =B37*C37 -> 0 | G37: 1550 nm | H37: =$I$11*$D$39+$I$12 -> 0.300636 | I37: =$I$11*$D$45+$I$12 -> 0.30051 | J37: =$I$11*$I$51+$I$12 -> 0.3006
A38: Salón | B38: ='1.Distancias'!B90 -> 2.12 | C38: 1 | D38: =B38*C38 -> 2.12
A39: Dimensionado por vivienda tipo 2º - 8º | D39: =SUM(D34:D38) -> 2.12
A40: Dorm.3 | B40: ='1.Distancias'!B76 -> 2.67 | C40: 0 | D40: =B40*C40 -> 0
A41: Dorm.2 | B41: ='1.Distancias'!B77 -> 6.37 | C41: 0 | D41: =B41*C41 -> 0 | G41: Distribución de las BAT FO
A42: Dorm.Ppal. | B42: ='1.Distancias'!B78 -> 5.45 | C42: 0 | D42: =B42*C42 -> 0 | G42: Vivienda tipo | H42: 1º | I42: 2º - 8º | J42: Ático
A43: Cocina | B43: ='1.Distancias'!B79 -> 0.85 | C43: 0 | D43: =B43*C43 -> 0 | G43: Dorm.3 | H43: 0 | I43: 0 | J43: 0
A44: Salón | B44: ='1.Distancias'!B80 -> 1.7 | C44: 1 | D44: =B44*C44 -> 1.7 | G44: Dorm.2 | H44: 0 | I44: 0 | J44: 0
A45: Dimensionado por vivienda tipo Ático | D45: =SUM(D40:D44) -> 1.7 | G45: Dorm.Ppal. | H45: 0 | I45: 0 | J45: 0
A46: Dorm.3 | B46: ='1.Distancias'!B6 -> 7.97 | C46: 0 | D46: =B46*C46 -> 0 | G46: Cocina | H46: 0 | I46: 0 | J46: 0
A47: Dorm.2 | B47: ='1.Distancias'!B7 -> 10.29 | C47: 0 | D47: =B47*C47 -> 0 | G47: Salón | H47: 1 | I47: 1 | J47: 1
A48: Dorm.Ppal. | B48: ='1.Distancias'!B8 -> 10.95 | C48: 0 | D48: =B48*C48 -> 0 | G48: Total | H48: =SUM(H43:H47) -> 1 | I48: =SUM(I43:I47) -> 1 | J48: =SUM(J43:J47) -> 1
A49: Cocina | B49: ='1.Distancias'!B9 -> 8.1 | C49: 0 | D49: =B49*C49 -> 0
...

Sheet Fabricante
A1: Se exponen aquí los elementos elegidos para el diseño a partir de los datos suministrados del fabricante.
A7: Elemento | B7: Nombre en Proyecto (Tipo) | C7: Código fabricante | D7: Nº unidades | E7: Servicio/s de uso | F7: Url
A8: Antena FM-Radio | B8: - | C8: 1201 | D8: 1 | E8: FM-Radio | F8: https://www.televes.com/es/1201-antena-de-fm-recepcion-de-radio.html
A9: Antena DAB-Radio | B9: - | C9: 1050 | D9: 1 | E9: DAB-Radio | F9: https://www.televes.com/es/1050xx-antenadab-antena-de-dab-biii.html
A10: Antena COFDM-TV | B10: - | C10: 149921 | D10: 1 | E10: TDT | F10: https://www.televes.com/es/catalog/product/view/id/3679/s/14992x_DATBOSS_700-Antena%20DAT%20BOSS%20UHF,%202%C2%BA%20Dividendo%20Digital%20(LTE700)/category/6/
A11: Antena satélite | B11: - | C11: 793002 | D11: 2 | E11: Sat. A/D | F11: https://www.televes.com/es/7930xx-isd630-parabola-de-aluminio-isd-630-63x57cm.html
A12: LNB | B12: - | C12: 7475 | D12: 1 | E12: Sat. A/D | F12: https://www.televes.com/es/lnb-single-lnb-offset-single-universal-1-salida-ha-va-hb-vb.html
A13: Amplificador monocanal | B13: - | C13: 509012 | D13: 1 | E13: FM-Radio | F13: https://www.televes.com/es/509012-amplificador-monocanal-t12-fm-dab-88-108-174-230mhz.html
A14: Amplificador monocanal | B14: - | C14: 509012 | D14: 1 | E14: DAB-Radio | F14: https://www.televes.com/es/509012-amplificador-monocanal-t12-fm-dab-88-108-174-230mhz.html
A15: Amplificador monocanal | B15: - | C15: 509812 | D15: 1 | E15: TDT | F15: https://www.televes.com/es/509812-amplificador-monocanal-selectivo-t12-uhf-tdt-470-862mhz.html
A16: Fuente de alimentación para monocanales | B16: - | C16: 549812 | D16: 1 | E16: FM-Radio, DAB-Radio, TDT | F16: https://www.televes.com/es/catalog/product/view/id/61/s/549812-Fuente%20de%20alimentaci%C3%B3n%20T12%2024V%20-%202,5A%20(60W)/category/236/
A17: Amplificador FI | B17: - | E17: Sat. A/D | F17: https://www.televes.com/es/508012-amplificador-t12-fi-sat-950-2150mhz.html
A18: Mezclador de bandas | B18: - | C18: 745210 | D18: 2 | E18: FM-Radio, DAB-Radio, TDT | F18: https://www.televes.com/es/mezclador-smatv-mezclador-de-se-al-terrestre-y-satelite-2-entradas-matv-fi.html
A19: Derivador | B19: A | C19: 519322 | D19: 2 | E19: FM-Radio, DAB-Radio, TDT | F19: https://www.televes.com/es/519322-derivador-f-2d-5-2400mhz-12db.html
A20: Derivador | B20: B | C20: 519323 | D20: 4 | E20: FM-Radio, DAB-Radio, TDT | F20: https://www.televes.com/es/519323-derivador-f-2d-5-2400mhz-16db.html
A21: Derivador | B21: C | C21: 519324 | D21: 6 | E21: FM-Radio, DAB-Radio, TDT | F21: https://www.televes.com/es/519324-derivador-f-2d-5-2400mhz-20db.html
A22: Derivador | B22: D | C22: 519325 | D22: 6 | E22: FM-Radio, DAB-Radio, TDT | F22: https://www.televes.com/es/catalog/product/view/id/3491/s/519325-Derivador%20F%202D%205...2400MHz%2024dB/category/384/
A23: Repartidor banda terrena | B23: 1 | C23: 453003 | D23: 1 | E23: Todos | F23: https://www.televes.com/es/453003-repartidor-f-2d-5-1220mhz-4db-docsis-3-1.html
A24: PAU repartidor | B24: 2 | C24: 519535 | D24: 17 | E24: Todos | F24: https://www.televes.com/es/519535-repartidor-con-pau-f-5d-5-2400mhz-11-10db.html
A25: Cable coaxial | B25: T-100 | C25: 2126 | E25: Todos | F25: https://www.televes.com/es/2126xx-coaxial-t100-eca-16vatc-cable-coaxial-t100-16vatc-euroclase-eca-y-blindaje-clase-a.html
A26: Toma RTV | B26: - | C26: 4301 | D26: 85 | E26: Todos | F26: https://www.televes.com/es/52x6-4301-toma-terminal-toma-terminal-separadora-2-conectores-fm-tv-sat.html
A27: Resistencia 75 ohm | F27: https://www.televes.com/es/4058-405802-carga-terminal-75-ohm-tipo-f-sin-bloqueo-de-dc.html
A29: Cable 2FO | C29: 231902 | D29: 544.49 | F29: https://www.televes.com/es/catalog/product/view/id/3697/s/2319xx_FK2_interior-Cable%20FK2%20monomodo%202%20fibras,%20Euroclase%20Dca%20y%20LSFH,%20de%20interior/category/1174/
A30: Conector SC/APC | C30: 2329 | D30: 52 | F30: https://www.televes.com/es/2329-conector-sc-apc.html
A31: Caja de segregación | C31: 231310 | D31: 9 | F31: https://www.televes.com/es/catalog/product/view/id/375/s/231310-Registro%20secundario%20final%20de%20fibra%20%C3%B3ptica/category/1218/
A32: Roseta óptica | C32: 233232 | D32: 17 | F32: https://www.televes.com/es/233232-roseta-terminal-de-fibra-optica-para-adaptacion-de-tomas-en-superficie.html
A33: Patch Panel de fibra óptica 32 puertos
A35: Aqara Presence Sensor FP2 | D35: 85 | F35: https://eu.aqara.com/es-eu/products/aqara-presence-sensor-fp2
A36: Aqara Motion Sensor P1 | D36: 51 | F36: https://eu.aqara.com/es-eu/products/aqara-motion-sensor-p1
A37: HomePilot Gateway | D37: 17
